Workbook

Sheet Read Me
A1: Aisle & Co. — Financial Model
A2: "Wedding-day care for your littlest guests — two-legged and four."
A3: Northeast Florida | Jacksonville · St. Augustine · Ponte Vedra · Amelia Island · Palm Coast · Daytona
A5: How to use this model:
A6: 1. Open the 'Assumptions' tab. Every blue cell is an input you can change.
A7: 2. The model recalculates automatically.
A8: 3. Color coding:
A9: Blue = hardcoded input (edit these to flex the model)
A10: Black = formula / calculation
A11: Green = cross-sheet link
A12: Yellow highlight = key output worth watching
A14: Sheet guide:
... A34: Drafted by: CEO mode - Founding Plan v1.1 (May 2026)

Sheet Assumptions
A1: Aisle & Co. — Key Assumptions
A2: Wedding-day childcare + pet sitting | NE Florida
A3: Blue = input (edit to flex). Black = formula. Green = cross-sheet link.
A5: Pricing inputs (charged to client)
A6: Lead sitter hourly rate | B6: 65 | C6: $/hr
A7: Additional sitter hourly rate | B7: 50 | C7: $/hr
A8: Aisle Sitters setup fee | B8: 50 | C8: flat
A9: Late-night surcharge (after 11pm) | B9: 15 | C9: $/hr/sitter
A10: Pet of Honor — Standard | B10: 475 | C10: flat
A11: Pet of Honor — Premium | B11: 695 | C11: flat
A12: Weekend Pet Care package | B12: 1275 | C12: flat
A13: Multi-pet add-on (per pet) | B13: 150 | C13: flat
A14: Boarding per night | B14: 95 | C14: $/night
A15: Travel surcharge | B15: 1.5 | C15: $/mile >25mi
A16: Activities upcharge (typical) | B16: 150 | C16: flat / event
A18: Sitter / handler pay (paid by us)
A19: Lead sitter pay | B19: 32 | C19: $/hr
A20: Additional sitter pay | B20: 25 | C20: $/hr
A21: Pet handler pay (Standard) | B21: 130 | C21: flat
A22: Pet handler pay (Premium) | B22: 195 | C22: flat
A23: Weekend Pet handler pay | B23: 425 | C23: flat
A24: Supplies cost per child (activity kit) | B24: 7.5 | C24: $/child
A25: Supplies/transport per pet event | B25: 30 | C25: $/event
A27: Typical Aisle event sizing
A28: Avg kids per Aisle event | B28: 8 | C28: kids
A29: Avg sitters per Aisle event | B29: 2 | C29: sitters
A30: Avg event hours (Aisle Sitters) | B30: 6 | C30: hours
A31: Wedding Weekend avg revenue (Signature) | B31: 2400 | C31: $/event
A32: Sitter hours per Wedding Weekend | B32: 12 | C32: hr/event
A34: Volume & service mix by year
B35: Year 1 | C35: Year 2 | D35: Year 3
A36: Events booked | B36: 30 | C36: 80 | D36: 180
A37: Avg ticket / event | B37: 650 | C37: 750 | D37: 850 | E37: Y1 launch mix is mostly Aisle; ramps with Weekend %
A38: % mix — Aisle Sitters only | B38: 0.65 | C38: 0.55 | D38: 0.45
A39: % mix — Pet of Honor only | B39: 0.25 | C39: 0.25 | D39: 0.25
A40: % mix — Wedding Weekend (combo) | B40: 0.1 | C40: 0.2 | D40: 0.3
A42: Fixed costs (annual baseline)
A43: Insurance (GL + pet rider + bond) | B43: 1400
A44: Software stack (CRM, QB, Workspace, etc.) | B44: 2000
A45: Website + domain (Squarespace) | B45: 280
...

Sheet Unit Economics
A1: Unit Economics — Per-Event Math
A2: What does each service type look like at typical event size? Margins drive scenarios.
A4: Aisle Sitters — typical event (driven by Assumptions sizing)
A5: Lead sitter revenue ($/hr × hours) | B5: =Assumptions!B6*Assumptions!B30 -> 390
A6: Additional sitter revenue ($/hr × hours × addl sitters) | B6: =Assumptions!B7*Assumptions!B30*(Assumptions!B29-1) -> 300
A7: Setup fee | B7: =Assumptions!B8 -> 50
A8: Activities upcharge | B8: =Assumptions!B16 -> 150
A9: Total revenue | B9: =SUM(B5:B8) -> 890
A10: Lead sitter pay ($/hr × hours) | B10: =Assumptions!B19*Assumptions!B30 -> 192
A11: Additional sitter pay ($/hr × hours × addl sitters) | B11: =Assumptions!B20*Assumptions!B30*(Assumptions!B29-1) -> 150
A12: Activity kits / supplies ($/child × kids) | B12: =Assumptions!B24*Assumptions!B28 -> 60
A13: Total COGS | B13: =SUM(B10:B12) -> 402
A14: Gross profit | B14: =B9-B13 -> 488
A15: Gross margin | B15: =B14/B9 -> 0.54831461
A17: Pet of Honor — Standard package
A18: Standard package revenue | B18: =Assumptions!B10 -> 475
A19: Handler pay (flat per package) | B19: =Assumptions!B21 -> 130
A20: Supplies / transport | B20: =Assumptions!B25 -> 30
A21: Total COGS | B21: =SUM(B19:B20) -> 160
A22: Gross profit | B22: =B18-B21 -> 315
A23: Gross margin | B23: =B22/B18 -> 0.66315789
A25: Wedding Weekend — Signature combo
A26: Package revenue (Signature avg) | B26: =Assumptions!B31 -> 2400
A27: Sitter pay (12 hr × 2 sitters @ blended rate) | B27: =Assumptions!B32*Assumptions!B29*((Assumptions!B19+Assumptions!B20)/2) -> 684
A28: Pet handler pay (Standard) | B28: =Assumptions!B21 -> 130
A29: Supplies (kids kits + pet) | B29: =Assumptions!B24*Assumptions!B28+Assumptions!B25 -> 90
A30: Total COGS | B30: =SUM(B27:B29) -> 904
A31: Gross profit | B31: =B26-B30 -> 1496
A32: Gross margin | B32: =B31/B26 -> 0.62333333
A34: Blended unit economics by year (mix-weighted)
A35: Service | B35: Per-event revenue | C35: Per-event COGS | D35: Per-event GP | E35: Y1 mix | F35: Y2 mix
A36: Aisle Sitters | B36: =B9 -> 890 | C36: =B13 -> 402 | D36: =B36-C36 -> 488 | E36: =Assumptions!B38 -> 0.65 | F36: =Assumptions!C38 -> 0.55
A37: Pet of Honor | B37: =B18 -> 475 | C37: =B21 -> 160 | D37: =B37-C37 -> 315 | E37: =Assumptions!B39 -> 0.25 | F37: =Assumptions!C39 -> 0.25
A38: Wedding Weekend | B38: =B26 -> 2400 | C38: =B30 -> 904 | D38: =B38-C38 -> 1496 | E38: =Assumptions!B40 -> 0.1 | F38: =Assumptions!C40 -> 0.2
A39: Y1 blended per-event (computed) | B39: =SUMPRODUCT(B36:B38,E36:E38) -> 937.25 | C39: =SUMPRODUCT(C36:C38,E36:E38) -> 391.7 | D39: =B39-C39 -> 545.55 | E39: Reference only — P&L uses Avg Ticket inputs from Assumptions

Sheet Startup Costs
A1: Startup Costs (pre-revenue, Months 1-3)
A2: One-time launch capex. Founder injects ~$10K to be safe.
A4: Item | B4: Cost | C4: Notes
A5: LLC formation + DBA + business tax receipt | B5: 250 | C5: Sunbiz, county
A6: Attorney for MSA + waivers | B6: 1000 | C6: One-time drafting
A7: Insurance (annual, paid up front) | B7: 1400 | C7: GL + pet rider + bond
A8: Brand identity (logo, basic guidelines) | B8: 1200 | C8: Local designer or 99designs
A9: Website + domain + Squarespace setup | B9: 600 | C9: Including 12 mo hosting
A10: HoneyBook + QuickBooks + Workspace (3 mo prepaid) | B10: 300
A11: Initial activity kits + branded supplies (10 events) | B11: 800 | C11: Reusable + consumable mix
A12: Branded leashes / collars / pet kit | B12: 400 | C12: 5 events of pet inventory
A13: Background checks (initial 8 sitters) | B13: 700 | C13: AHCA Level 2 + Checkr
A14: The Knot Storefront (3 mo) | B14: 900
A15: Photography for marketing (styled shoot) | B15: 1500 | C15: 1 styled shoot, 30+ photos
A16: Misc (printing, gift boxes for venues) | B16: 450 | C16: 10 venue gift drops
A17: TOTAL STARTUP | B17: =SUM(B5:B16) -> 9500

Sheet Year 1 Monthly P&L
A1: Year 1 Monthly P&L
A2: Seasonality reflects NE FL: October peak, Mar-May secondary, Jul-Sep trough.
B4: M1 | C4: M2 | D4: M3 | E4: M4 Apr | F4: M5 May | G4: M6 Jun | H4: M7 Jul | I4: M8 Aug | J4: M9 Sep | K4: M10 Oct | L4: M11 Nov | M4: M12 Dec | N4: Year 1
A5: Events | B5: 0 | C5: 0 | D5: 0 | E5: 2 | F5: 3 | G5: 2 | H5: 1 | I5: 1 | J5: 2 | K5: 8 | L5: 6 | M5: 5 | N5: =SUM(B5:M5) -> 30
A6: Avg revenue / event (Y1) | B6: =Assumptions!B37 -> 650 | C6: =Assumptions!B37 -> 650 | D6: =Assumptions!B37 -> 650 | E6: =Assumptions!B37 -> 650 | F6: =Assumptions!B37 -> 650 | G6: =Assumptions!B37 -> 650 | H6: =Assumptions!B37 -> 650 | I6: =Assumptions!B37 -> 650 | J6: =Assumptions!B37 -> 650 | K6: =Assumptions!B37 -> 650 | L6: =Assumptions!B37 -> 650 | M6: =Assumptions!B37 -> 650
A7: Revenue | B7: =B5*B6 -> 0 | C7: =C5*C6 -> 0 | D7: =D5*D6 -> 0 | E7: =E5*E6 -> 1300 | F7: =F5*F6 -> 1950 | G7: =G5*G6 -> 1300 | H7: =H5*H6 -> 650 | I7: =I5*I6 -> 650 | ... M7: =M5*M6 -> 3250 | N7: =SUM(B7:M7) -> 19500
A8: Gross margin % | B8: =(Assumptions!B38*('Unit Economics'!B9-'Unit Economics'!B13)+Assumptions!B39*('Unit Economics'!B18-'Unit Economics'!B21)+Assumptions!B40*('Unit Economics'!B26-'Unit Economics'!B30))/(Assumptions!B38*'Unit Economics'!B9+Assumptions!B39*'Unit Economics'!B18+Assumptions!B40*'Unit Economics'!B26) -> 0.58207522 | C8: =(Assumptions!B38*('Unit Economics'!B9-'Unit Economics'!B13)+Assumptions!B39*('Unit Economics'!B18-'Unit Economics'!B21)+Assumptions!B40*('Unit Economics'!B26-'Unit Economics'!B30))/(Assumptions!B38*'Unit Economics'!B9+Assumptions!B39*'Unit Economics'!B18+Assumptions!B40*'Unit Economics'!B26) -> 0.58207522 | D8: =(Assumptions!B38*('Unit Economics'!B9-'Unit Economics'!B13)+Assumptions!B39*('Unit Economics'!B18-'Unit Economics'!B21)+Assumptions!B40*('Unit Economics'!B26-'Unit Economics'!B30))/(Assumptions!B38*'Unit Economics'!B9+Assumptions!B39*'Unit Economics'!B18+Assumptions!B40*'Unit Economics'!B26) -> 0.58207522 | E8: =(Assumptions!B38*('Unit Economics'!B9-'Unit Economics'!B13)+Assumptions!B39*('Unit Economics'!B18-'Unit Economics'!B21)+Assumptions!B40*('Unit Economics'!B26-'Unit Economics'!B30))/(Assumptions!B38*'Unit Economics'!B9+Assumptions!B39*'Unit Economics'!B18+Assumptions!B40*'Unit Economics'!B26) -> 0.58207522 | F8: =(Assumptions!B38*('Unit Economics'!B9-'Unit Economics'!B13)+Assumptions!B39*('Unit Economics'!B18-'Unit Economics'!B21)+Assumptions!B40*('Unit Economics'!B26-'Unit Economics'!B30))/(Assumptions!B38*'Unit Economics'!B9+Assumptions!B39*'Unit Economics'!B18+Assumptions!B40*'Unit Economics'!B26) -> 0.58207522 | G8: =(Assumptions!B38*('Unit Economics'!B9-'Unit Economics'!B13)+Assumptions!B39*('Unit Economics'!B18-'Unit Economics'!B21)+Assumptions!B40*('Unit Economics'!B26-'Unit Economics'!B30))/(Assumptions!B38*'Unit Economics'!B9+Assumptions!B39*'Unit Economics'!B18+Assumptions!B40*'Unit Economics'!B26) -> 0.58207522 | H8: =(Assumptions!B38*('Unit Economics'!B9-'Unit Economics'!B13)+Assumptions!B39*('Unit Economics'!B18-'Unit Economics'!B21)+Assumptions!B40*('Unit Economics'!B26-'Unit Economics'!B30))/(Assumptions!B38*'Unit Economics'!B9+Assumptions!B39*'Unit Economics'!B18+Assumptions!B40*'Unit Economics'!B26) -> 0.58207522 | I8: =(Assumptions!B38*('Unit Economics'!B9-'Unit Economics'!B13)+Assumptions!B39*('Unit Economics'!B18-'Unit Economics'!B21)+Assumptions!B40*('Unit Economics'!B26-'Unit Economics'!B30))/(Assumptions!B38*'Unit Economics'!B9+Assumptions!B39*'Unit Economics'!B18+Assumptions!B40*'Unit Economics'!B26) -> 0.58207522 | J8: =(Assumptions!B38*('Unit Economics'!B9-'Unit Economics'!B13)+Assumptions!B39*('Unit Economics'!B18-'Unit Economics'!B21)+Assumptions!B40*('Unit Economics'!B26-'Unit Economics'!B30))/(Assumptions!B38*'Unit Economics'!B9+Assumptions!B39*'Unit Economics'!B18+Assumptions!B40*'Unit Economics'!B26) -> 0.58207522 | K8: =(Assumptions!B38*('Unit Economics'!B9-'Unit Economics'!B13)+Assumptions!B39*('Unit Economics'!B18-'Unit Economics'!B21)+Assumptions!B40*('Unit Economics'!B26-'Unit Economics'!B30))/(Assumptions!B38*'Unit Economics'!B9+Assumptions!B39*'Unit Economics'!B18+Assumptions!B40*'Unit Economics'!B26) -> 0.58207522 | L8: =(Assumptions!B38*('Unit Economics'!B9-'Unit Economics'!B13)+Assumptions!B39*('Unit Economics'!B18-'Unit Economics'!B21)+Assumptions!B40*('Unit Economics'!B26-'Unit Economics'!B30))/(Assumptions!B38*'Unit Economics'!B9+Assumptions!B39*'Unit Economics'!B18+Assumptions!B40*'Unit Economics'!B26) -> 0.58207522 | M8: =(Assumptions!B38*('Unit Economics'!B9-'Unit Economics'!B13)+Assumptions!B39*('Unit Economics'!B18-'Unit Economics'!B21)+Assumptions!B40*('Unit Economics'!B26-'Unit Economics'!B30))/(Assumptions!B38*'Unit Economics'!B9+Assumptions!B39*'Unit Economics'!B18+Assumptions!B40*'Unit Economics'!B26) -> 0.58207522
A9: COGS | B9: =B7*(1-B8) -> 0 | C9: =C7*(1-C8) -> 0 | D9: =D7*(1-D8) -> 0 | E9: =E7*(1-E8) -> 543.30221 | F9: =F7*(1-F8) -> 814.95332 | G9: =G7*(1-G8) -> 543.30221 | H9: =H7*(1-H8) -> 271.65111 | I9: =I7*(1-I8) -> 271.65111 | ... M9: =M7*(1-M8) -> 1358.2555 | N9: =SUM(B9:M9) -> 8149.5332
A10: Gross profit | B10: =B7-B9 -> 0 | C10: =C7-C9 -> 0 | D10: =D7-D9 -> 0 | E10: =E7-E9 -> 756.69779 | F10: =F7-F9 -> 1135.0467 | G10: =G7-G9 -> 756.69779 | H10: =H7-H9 -> 378.34889 | I10: =I7-I9 -> 378.34889 | ... M10: =M7-M9 -> 1891.7445 | N10: =SUM(B10:M10) -> 11350.467
A12: Fixed costs (allocated monthly) | B12: =Assumptions!B52/12 -> 948.33333 | C12: =Assumptions!B52/12 -> 948.33333 | D12: =Assumptions!B52/12 -> 948.33333 | E12: =Assumptions!B52/12 -> 948.33333 | F12: =Assumptions!B52/12 -> 948.33333 | G12: =Assumptions!B52/12 -> 948.33333 | H12: =Assumptions!B52/12 -> 948.33333 | I12: =Assumptions!B52/12 -> 948.33333 | J12: =Assumptions!B52/12 -> 948.33333 | K12: =Assumptions!B52/12 -> 948.33333 | L12: =Assumptions!B52/12 -> 948.33333 | M12: =Assumptions!B52/12 -> 948.33333 | N12: =SUM(B12:M12) -> 11380
A13: Startup amortized (M1-3) | B13: ='Startup Costs'!B17/3 -> 3166.6667 | C13: ='Startup Costs'!B17/3 -> 3166.6667 | D13: ='Startup Costs'!B17/3 -> 3166.6667 | E13: 0 | F13: 0 | G13: 0 | H13: 0 | I13: 0 | J13: 0 | K13: 0 | L13: 0 | M13: 0 | N13: =SUM(B13:M13) -> 9500
A14: Monthly net | B14: =B10-B12-B13 -> -4115 | C14: =C10-C12-C13 -> -4115 | D14: =D10-D12-D13 -> -4115 | E14: =E10-E12-E13 -> -191.63555 | F14: =F10-F12-F13 -> 186.71335 | G14: =G10-G12-G13 -> -191.63555 | H14: =H10-H12-H13 -> -569.98444 | I14: =I10-I12-I13 -> -569.98444 | ... M14: =M10-M12-M13 -> 943.41113 | N14: =SUM(B14:M14) -> -9529.5332
A15: Cumulative net | B15: =B14 -> -4115 | C15: =B15+C14 -> -8230 | D15: =C15+D14 -> -12345 | E15: =D15+E14 -> -12536.636 | F15: =E15+F14 -> -12349.922 | G15: =F15+G14 -> -12541.558 | H15: =G15+H14 -> -13111.542 | I15: =H15+I14 -> -13681.527 | J15: =I15+J14 -> -13873.162 | ... M15: =L15+M14 -> -9529.5332

Sheet Multi-Year Projection
A1: 3-Year Projection
A2: Y1 launch. Y2 side income materialized. Y3 fork: stay side or hire to scale.
A4: Metric | B4: Year 1 | C4: Year 2 | D4: Year 3 | E4: Notes
A5: Events booked | B5: =Assumptions!B36 -> 30 | C5: =Assumptions!C36 -> 80 | D5: =Assumptions!D36 -> 180 | E5: Volume ramps with venue list inclusion
A6: Avg revenue / event | B6: =Assumptions!B37 -> 650 | C6: =Assumptions!C37 -> 750 | D6: =Assumptions!D37 -> 850 | E6: Mix shift toward higher-ticket Weekend lifts avg
A7: Gross revenue | B7: =B5*B6 -> 19500 | C7: =C5*C6 -> 60000 | D7: =D5*D6 -> 153000
A8: Blended GM% (mix-weighted) | B8: =(Assumptions!B38*('Unit Economics'!B9-'Unit Economics'!B13)+Assumptions!B39*('Unit Economics'!B18-'Unit Economics'!B21)+Assumptions!B40*('Unit Economics'!B26-'Unit Economics'!B30))/(Assumptions!B38*'Unit Economics'!B9+Assumptions!B39*'Unit Economics'!B18+Assumptions!B40*'Unit Economics'!B26) -> 0.58207522 | C8: =(Assumptions!C38*('Unit Economics'!B9-'Unit Economics'!B13)+Assumptions!C39*('Unit Economics'!B18-'Unit Economics'!B21)+Assumptions!C40*('Unit Economics'!B26-'Unit Economics'!B30))/(Assumptions!C38*'Unit Economics'!B9+Assumptions!C39*'Unit Economics'!B18+Assumptions!C40*'Unit Economics'!B26) -> 0.59393522 | D8: =(Assumptions!D38*('Unit Economics'!B9-'Unit Economics'!B13)+Assumptions!D39*('Unit Economics'!B18-'Unit Economics'!B21)+Assumptions!D40*('Unit Economics'!B26-'Unit Economics'!B30))/(Assumptions!D38*'Unit Economics'!B9+Assumptions!D39*'Unit Economics'!B18+Assumptions!D40*'Unit Economics'!B26) -> 0.60290498
A9: COGS | B9: =B7*(1-B8) -> 8149.5332 | C9: =C7*(1-C8) -> 24363.887 | D9: =D7*(1-D8) -> 60755.538
A10: Gross profit | B10: =B7-B9 -> 11350.467 | C10: =C7-C9 -> 35636.113 | D10: =D7-D9 -> 92244.462
A11: Fixed costs | B11: =Assumptions!B52 -> 11380 | C11: =Assumptions!B52*1.5 -> 17070 | D11: =Assumptions!B52*2.5+45000 -> 73450 | E11: Y2 +50% (mktg); Y3 adds Ops Lead salary $45K
A12: Pre-tax net to founders | B12: =B10-B11 -> -29.533209 | C12: =C10-C11 -> 18566.113 | D12: =D10-D11 -> 18794.462
A13: Net margin | B13: =B12/B7 -> -0.0015145235 | C13: =C12/C7 -> 0.30943522 | D13: =D12/D7 -> 0.12283962
A14: Roster (sitters + handlers) | B14: 8-12 | C14: 18-25 | D14: 35-50

Sheet Scenarios
A1: Year 1 Sensitivity Scenarios
A2: What changes the Year 1 outcome
A4: Scenario | B4: Events | C4: Avg ticket | D4: Pre-tax net (Y1) | E4: Pre-tax net (Y1, ex-startup) | F4: Trigger / how we get there
A5: Conservative | B5: 18 | C5: 600 | D5: =B5*C5*((Assumptions!B38*('Unit Economics'!B9-'Unit Economics'!B13)+Assumptions!B39*('Unit Economics'!B18-'Unit Economics'!B21)+Assumptions!B40*('Unit Economics'!B26-'Unit Economics'!B30))/(Assumptions!B38*'Unit Economics'!B9+Assumptions!B39*'Unit Economics'!B18+Assumptions!B40*'Unit Economics'!B26))-Assumptions!B52-'Startup Costs'!B17 -> -14593.588 | E5: =B5*C5*((Assumptions!B38*('Unit Economics'!B9-'Unit Economics'!B13)+Assumptions!B39*('Unit Economics'!B18-'Unit Economics'!B21)+Assumptions!B40*('Unit Economics'!B26-'Unit Economics'!B30))/(Assumptions!B38*'Unit Economics'!B9+Assumptions!B39*'Unit Economics'!B18+Assumptions!B40*'Unit Economics'!B26))-Assumptions!B52 -> -5093.5876 | F5: No venue list wins; only direct inquiries
A6: Base | B6: 30 | C6: 650 | D6: =B6*C6*((Assumptions!B38*('Unit Economics'!B9-'Unit Economics'!B13)+Assumptions!B39*('Unit Economics'!B18-'Unit Economics'!B21)+Assumptions!B40*('Unit Economics'!B26-'Unit Economics'!B30))/(Assumptions!B38*'Unit Economics'!B9+Assumptions!B39*'Unit Economics'!B18+Assumptions!B40*'Unit Economics'!B26))-Assumptions!B52-'Startup Costs'!B17 -> -9529.5332 | E6: =B6*C6*((Assumptions!B38*('Unit Economics'!B9-'Unit Economics'!B13)+Assumptions!B39*('Unit Economics'!B18-'Unit Economics'!B21)+Assumptions!B40*('Unit Economics'!B26-'Unit Economics'!B30))/(Assumptions!B38*'Unit Economics'!B9+Assumptions!B39*'Unit Economics'!B18+Assumptions!B40*'Unit Economics'!B26))-Assumptions!B52 -> -29.533209 | F6: 1-2 venue lists, 2-3 planner referrals
A7: Aggressive | B7: 50 | C7: 700 | D7: =B7*C7*((Assumptions!B38*('Unit Economics'!B9-'Unit Economics'!B13)+Assumptions!B39*('Unit Economics'!B18-'Unit Economics'!B21)+Assumptions!B40*('Unit Economics'!B26-'Unit Economics'!B30))/(Assumptions!B38*'Unit Economics'!B9+Assumptions!B39*'Unit Economics'!B18+Assumptions!B40*'Unit Economics'!B26))-Assumptions!B52-'Startup Costs'!B17 -> -507.3673 | E7: =B7*C7*((Assumptions!B38*('Unit Economics'!B9-'Unit Economics'!B13)+Assumptions!B39*('Unit Economics'!B18-'Unit Economics'!B21)+Assumptions!B40*('Unit Economics'!B26-'Unit Economics'!B30))/(Assumptions!B38*'Unit Economics'!B9+Assumptions!B39*'Unit Economics'!B18+Assumptions!B40*'Unit Economics'!B26))-Assumptions!B52 -> 8992.6327 | F7: Treasury Group + Omni or Ritz on list by month 6
A8: Stretch | B8: 70 | C8: 750 | D8: =B8*C8*((Assumptions!B38*('Unit Economics'!B9-'Unit Economics'!B13)+Assumptions!B39*('Unit Economics'!B18-'Unit Economics'!B21)+Assumptions!B40*('Unit Economics'!B26-'Unit Economics'!B30))/(Assumptions!B38*'Unit Economics'!B9+Assumptions!B39*'Unit Economics'!B18+Assumptions!B40*'Unit Economics'!B26))-Assumptions!B52-'Startup Costs'!B17 -> 9678.9491 | E8: =B8*C8*((Assumptions!B38*('Unit Economics'!B9-'Unit Economics'!B13)+Assumptions!B39*('Unit Economics'!B18-'Unit Economics'!B21)+Assumptions!B40*('Unit Economics'!B26-'Unit Economics'!B30))/(Assumptions!B38*'Unit Economics'!B9+Assumptions!B39*'Unit Economics'!B18+Assumptions!B40*'Unit Economics'!B26))-Assumptions!B52 -> 19178.949 | F8: All Tier 1 venues + featured editorial coverage
A11: Breakeven analysis (Year 1, post-launch steady-state)
A12: Per-event contribution margin (Y1 mix) | B12: =Assumptions!B37*((Assumptions!B38*('Unit Economics'!B9-'Unit Economics'!B13)+Assumptions!B39*('Unit Economics'!B18-'Unit Economics'!B21)+Assumptions!B40*('Unit Economics'!B26-'Unit Economics'!B30))/(Assumptions!B38*'Unit Economics'!B9+Assumptions!B39*'Unit Economics'!B18+Assumptions!B40*'Unit Economics'!B26)) -> 378.34889
A13: Annual fixed (steady-state) | B13: =Assumptions!B52 -> 11380
A14: Breakeven events (steady-state, ex-startup) | B14: =B13/B12 -> 30.078058
A15: Breakeven events (incl startup, Y1) | B15: =(B13+'Startup Costs'!B17)/B12 -> 55.187158
